<?xml version="1.0" ?>
<!-- =================================================================================== -->
<!-- |    This document was autogenerated by xacro from model.urdf.xacro               | -->
<!-- |    EDITING THIS FILE BY HAND IS NOT RECOMMENDED                                 | -->
<!-- =================================================================================== -->
<robot name="rrbot">
  <!-- ======================================== -->
  <!-- Reference coordinate system              -->
  <!-- ======================================== -->
  <link name="world"/>
  <!-- ======================================== -->
  <!-- Definitions of materials                 -->
  <!-- ======================================== -->
  <material name="red">
    <color rgba="1.0 0.0 0.0 1.0"/>
  </material>
  <material name="green">
    <color rgba="0.0 0.6 0.0 1.0"/>
  </material>
  <material name="blue">
    <color rgba="0.0 0.0 1.0 1.0"/>
  </material>
  <!-- ======================================== -->
  <!-- Linkages                                 -->
  <!-- ======================================== -->
  <!-- base_link -->
  <link name="base_link">
    <visual>
      <origin rpy="0.0 0.0 0.0" xyz="0.0 0.0 0.15"/>
      <geometry>
        <box size="0.3 0.3 0.3"/>
      </geometry>
      <material name="red"/>
    </visual>
    <collision>
      <origin rpy="0.0 0.0 0.0" xyz="0.0 0.0 0.15"/>
      <geometry>
        <box size="0.3 0.3 0.3"/>
      </geometry>
    </collision>
    <inertial>
      <origin rpy="0.0 0.0 0.0" xyz="0.0 0.0 0.15"/>
      <mass value="10"/>
      <inertia ixx="0.05" ixy="0.0" ixz="0.0" iyy="0.05" iyz="0.0" izz="0.05"/>
    </inertial>
  </link>
  <!-- link1 -->
  <link name="link1">
    <visual>
      <origin rpy="0.0 0.0 0.0" xyz="0.0 0.0 0.25"/>
      <geometry>
        <cylinder length="0.5" radius="0.1"/>
      </geometry>
      <material name="green"/>
    </visual>
    <collision>
      <origin rpy="0.0 0.0 0.0" xyz="0.0 0.0 0.25"/>
      <geometry>
        <cylinder length="0.5" radius="0.1"/>
      </geometry>
    </collision>
    <inertial>
      <origin rpy="0.0 0.0 0.0" xyz="0.0 0.0 0.25"/>
      <mass value="10"/>
      <inertia ixx="0.05" ixy="0.0" ixz="0.0" iyy="0.05" iyz="0.0" izz="0.05"/>
    </inertial>
  </link>
  <!-- link 2 -->
  <link name="link2">
    <visual>
      <origin rpy="0.0 0.0 0.0" xyz="0.0 0.0 0.3"/>
      <geometry>
        <box size="0.1 0.1 0.6"/>
      </geometry>
      <material name="blue"/>
    </visual>
    <collision>
      <origin rpy="0.0 0.0 0.0" xyz="0.0 0.0 0.3"/>
      <geometry>
        <box size="0.1 0.1 0.6"/>
      </geometry>
    </collision>
    <inertial>
      <origin rpy="0.0 0.0 0.0" xyz="0.0 0.0 0.3"/>
      <mass value="10"/>
      <inertia ixx="0.05" ixy="0.0" ixz="0.0" iyy="0.05" iyz="0.0" izz="0.05"/>
    </inertial>
  </link>
  <!-- tool0 -->
  <link name="tool0"/>
  <!-- ======================================== -->
  <!-- Joints                                   -->
  <!-- ======================================== -->
  <!-- base_joint (parent -> base_link) -->
  <joint name="base_joint" type="fixed">
    <parent link="world"/>
    <child link="base_link"/>
    <origin rpy="0.0 0.0 0.0" xyz="0.0 0.0 0.0"/>
  </joint>
  <!-- joint1 (base_link -> link1) -->
  <joint name="joint1" type="revolute">
    <parent link="base_link"/>
    <child link="link1"/>
    <origin rpy="0.0 0.0 0.0" xyz="0.0 0.0 0.3"/>
    <axis xyz="0.0 0.0 1.0"/>
    <limit effort="1.0" lower="-6.632251157578453" upper="6.632251157578453" velocity="3.141592653589793"/>
    <dynamics damping="0.01" friction="0.0"/>
  </joint>
  <!-- joint2 (link1 -> link2) -->
  <joint name="joint2" type="revolute">
    <parent link="link1"/>
    <child link="link2"/>
    <origin rpy="0.0 -1.5707963267948966 0.0" xyz="0.0 0.0 0.5"/>
    <axis xyz="0.0 1.0 0.0"/>
    <limit effort="1.0" lower="-1.0471975511965976" upper="4.1887902047863905" velocity="3.141592653589793"/>
    <dynamics damping="0.01" friction="0.0"/>
  </joint>
  <!-- joint3 (link2 -> tool0) -->
  <joint name="joint3" type="fixed">
    <parent link="link2"/>
    <child link="tool0"/>
    <origin rpy="0.0 -3.141592653589793 -1.5707963267948966" xyz="0.0 0.0 0.6"/>
  </joint>
  <!-- ======================================== -->
  <!-- ros2_control                             -->
  <!-- ======================================== -->
  <ros2_control name="rrbot" type="system">
    <!-- ======================================== -->
    <!-- Hardwares                                -->
    <!-- ======================================== -->
    <hardware>
    </hardware>
    <!-- ======================================== -->
    <!-- Joints                                   -->
    <!-- ======================================== -->
    <!-- joint1 (base_link -> link1) -->
    <joint name="joint1">
      <!-- input -->
      <command_interface name="position"/>
      <command_interface name="velocity"/>
      <command_interface name="effort"/>
      <!-- output -->
      <state_interface name="position">
        <param name="initial_value">0.0</param>
      </state_interface>
      <state_interface name="velocity">
        <param name="initial_value">0.0</param>
      </state_interface>
      <state_interface name="effort">
        <param name="initial_value">0.0</param>
      </state_interface>
    </joint>
    <!-- joint2 (link1 -> link2) -->
    <joint name="joint2">
      <!-- input -->
      <command_interface name="position"/>
      <command_interface name="velocity"/>
      <command_interface name="effort"/>
      <!-- output -->
      <state_interface name="position">
        <param name="initial_value">0.0</param>
      </state_interface>
      <state_interface name="velocity">
        <param name="initial_value">0.0</param>
      </state_interface>
      <state_interface name="effort">
        <param name="initial_value">0.0</param>
      </state_interface>
    </joint>
    <!-- ======================================== -->
    <!-- Sensors                                  -->
    <!-- ======================================== -->
    <!-- tcp_sensor (Tool center point) -->
    <sensor name="tcp_sensor">
      <!-- output -->
      <state_interface name="fx"/>
      <state_interface name="fy"/>
      <state_interface name="fz"/>
      <state_interface name="tx"/>
      <state_interface name="ty"/>
      <state_interface name="tz"/>
      <!-- parameter -->
      <param name="frame_id">tool0</param>
    </sensor>
    <!-- ======================================== -->
    <!-- GPIOs                                    -->
    <!-- ======================================== -->
    <!-- flange_gpios -->
    <gpio name="flange_gpios">
      <!-- input -->
      <command_interface name="digital_out_0"/>
      <command_interface name="digital_out_1"/>
      <!-- output -->
      <state_interface name="digital_in_0"/>
      <state_interface name="digital_in_1"/>
      <state_interface name="digital_out_0"/>
      <state_interface name="digital_out_1"/>
    </gpio>
  </ros2_control>
</robot>
